Workbook

Sheet Summary
A1: InjuryCase — 5-year projection summary
A2: Planning model, not a forecast. Market counts and capture rates are estimates — see Assumptions and Sources. Edit blue cells on Assumptions.
A4: Conservative scenario
A5: ($, US) | B5: Year 1 | C5: Year 2 | D5: Year 3 | E5: Year 4 | F5: Year 5
A6: Customers (end of year) | B6: ='Monthly Conservative'!N31 -> 69.745778 | C6: ='Monthly Conservative'!Z31 -> 221.53052 | D6: ='Monthly Conservative'!AL31 -> 342.50396 | E6: ='Monthly Conservative'!AX31 -> 424.46998 | F6: ='Monthly Conservative'!BJ31 -> 477.92169
A7: ARR, end of year ($) | B7: ='Monthly Conservative'!N34 -> 43372.237 | C7: ='Monthly Conservative'!Z34 -> 139927.16 | D7: ='Monthly Conservative'!AL34 -> 219952.54 | E7: ='Monthly Conservative'!AX34 -> 274790.41 | F7: ='Monthly Conservative'!BJ34 -> 310551.31
A8: Revenue ($) | B8: =SUMPRODUCT(('Monthly Conservative'!$C$5:$BJ$5=1)*'Monthly Conservative'!$C$35:$BJ$35) -> 16663.88 | C8: =SUMPRODUCT(('Monthly Conservative'!$C$5:$BJ$5=2)*'Monthly Conservative'!$C$35:$BJ$35) -> 95655.85 | D8: =SUMPRODUCT(('Monthly Conservative'!$C$5:$BJ$5=3)*'Monthly Conservative'!$C$35:$BJ$35) -> 185143.32 | E8: =SUMPRODUCT(('Monthly Conservative'!$C$5:$BJ$5=4)*'Monthly Conservative'!$C$35:$BJ$35) -> 251590.61 | F8: =SUMPRODUCT(('Monthly Conservative'!$C$5:$BJ$5=5)*'Monthly Conservative'!$C$35:$BJ$35) -> 295422.25
A9: Gross profit ($) | B9: =SUMPRODUCT(('Monthly Conservative'!$C$5:$BJ$5=1)*'Monthly Conservative'!$C$42:$BJ$42) -> 9168.1708 | C9: =SUMPRODUCT(('Monthly Conservative'!$C$5:$BJ$5=2)*'Monthly Conservative'!$C$42:$BJ$42) -> 67154.331 | D9: =SUMPRODUCT(('Monthly Conservative'!$C$5:$BJ$5=3)*'Monthly Conservative'!$C$42:$BJ$42) -> 133499.71 | E9: =SUMPRODUCT(('Monthly Conservative'!$C$5:$BJ$5=4)*'Monthly Conservative'!$C$42:$BJ$42) -> 183172.41 | F9: =SUMPRODUCT(('Monthly Conservative'!$C$5:$BJ$5=5)*'Monthly Conservative'!$C$42:$BJ$42) -> 215963.98
A10: Gross margin % | B10: =IF(B8=0,0,B9/B8) -> 0.55018225 | C10: =IF(C8=0,0,C9/C8) -> 0.70204103 | D10: =IF(D8=0,0,D9/D8) -> 0.72106144 | E10: =IF(E8=0,0,E9/E8) -> 0.72805739 | F10: =IF(F8=0,0,F9/F8) -> 0.73103492
A11: Operating expenses ($) | B11: =SUMPRODUCT(('Monthly Conservative'!$C$5:$BJ$5=1)*'Monthly Conservative'!$C$52:$BJ$52) -> 141763.97 | C11: =SUMPRODUCT(('Monthly Conservative'!$C$5:$BJ$5=2)*'Monthly Conservative'!$C$52:$BJ$52) -> 235893.46 | D11: =SUMPRODUCT(('Monthly Conservative'!$C$5:$BJ$5=3)*'Monthly Conservative'!$C$52:$BJ$52) -> 412778.64 | E11: =SUMPRODUCT(('Monthly Conservative'!$C$5:$BJ$5=4)*'Monthly Conservative'!$C$52:$BJ$52) -> 485286.24 | F11: =SUMPRODUCT(('Monthly Conservative'!$C$5:$BJ$5=5)*'Monthly Conservative'!$C$52:$BJ$52) -> 585286.24
A12: EBITDA ($) | B12: =SUMPRODUCT(('Monthly Conservative'!$C$5:$BJ$5=1)*'Monthly Conservative'!$C$54:$BJ$54) -> -132595.8 | C12: =SUMPRODUCT(('Monthly Conservative'!$C$5:$BJ$5=2)*'Monthly Conservative'!$C$54:$BJ$54) -> -168739.13 | D12: =SUMPRODUCT(('Monthly Conservative'!$C$5:$BJ$5=3)*'Monthly Conservative'!$C$54:$BJ$54) -> -279278.93 | E12: =SUMPRODUCT(('Monthly Conservative'!$C$5:$BJ$5=4)*'Monthly Conservative'!$C$54:$BJ$54) -> -302113.83 | F12: =SUMPRODUCT(('Monthly Conservative'!$C$5:$BJ$5=5)*'Monthly Conservative'!$C$54:$BJ$54) -> -369322.26
A13: Cash, end of year ($) | B13: ='Monthly Conservative'!N55 -> -82595.796 | C13: ='Monthly Conservative'!Z55 -> -251334.93 | D13: ='Monthly Conservative'!AL55 -> -530613.86 | E13: ='Monthly Conservative'!AX55 -> -832727.69 | F13: ='Monthly Conservative'!BJ55 -> -1202050
A14: Lowest cash balance in 5 years ($) | B14: =MIN('Monthly Conservative'!$C$55:$BJ$55) -> -1202050
A15: Funding needed to stay above $0 ($) | B15: =MAX(0,-B14) -> 1202050
A16: First month with positive EBITDA | B16: =IFERROR(INDEX('Monthly Conservative'!$C$4:$BJ$4,MATCH(TRUE(),INDEX('Monthly Conservative'!$C$54:$BJ$54>0,0),0)),"Not within 5 years") -> Not within 5 years
A17: Customer lifetime value ÷ acquisition cost (year 5) | B17: =IF('Monthly Conservative'!BJ31=0,0,'Monthly Conservative'!BJ33/'Monthly Conservative'!BJ31*F10/Assumptions!$C$26/Assumptions!$C$27) -> 1.8850123
A18: Share of addressable practices reached (year 5) | B18: =F6/Assumptions!$D$11 -> 0.012209743
A21: Base scenario
A22: ($, US) | B22: Year 1 | C22: Year 2 | D22: Year 3 | E22: Year 4 | F22: Year 5
A23: Customers (end of year) | B23: ='Monthly Base'!N31 -> 150.53184 | C23: ='Monthly Base'!Z31 -> 433.05348 | D23: ='Monthly Base'!AL31 -> 672.4083 | E23: ='Monthly Base'!AX31 -> 851.95062 | F23: ='Monthly Base'!BJ31 -> 984.45255
A24: ARR, end of year ($) | B24: ='Monthly Base'!N34 -> 93603.766 | C24: ='Monthly Base'!Z34 -> 282015.76 | D24: ='Monthly Base'!AL34 -> 458340.65 | E24: ='Monthly Base'!AX34 -> 602421.05 | F24: ='Monthly Base'!BJ34 -> 719562.65
A25: Revenue ($) | B25: =SUMPRODUCT(('Monthly Base'!$C$5:$BJ$5=1)*'Monthly Base'!$C$35:$BJ$35) -> 35659.032 | C25: =SUMPRODUCT(('Monthly Base'!$C$5:$BJ$5=2)*'Monthly Base'!$C$35:$BJ$35) -> 197708.9 | D25: =SUMPRODUCT(('Monthly Base'!$C$5:$BJ$5=3)*'Monthly Base'!$C$35:$BJ$35) -> 384453.88 | E25: =SUMPRODUCT(('Monthly Base'!$C$5:$BJ$5=4)*'Monthly Base'!$C$35:$BJ$35) -> 545958.08 | F25: =SUMPRODUCT(('Monthly Base'!$C$5:$BJ$5=5)*'Monthly Base'!$C$35:$BJ$35) -> 676642.98
A26: Gross profit ($) | B26: =SUMPRODUCT(('Monthly Base'!$C$5:$BJ$5=1)*'Monthly Base'!$C$42:$BJ$42) -> 23038.553 | C26: =SUMPRODUCT(('Monthly Base'!$C$5:$BJ$5=2)*'Monthly Base'!$C$42:$BJ$42) -> 143410.44 | D26: =SUMPRODUCT(('Monthly Base'!$C$5:$BJ$5=3)*'Monthly Base'!$C$42:$BJ$42) -> 285693.63 | E26: =SUMPRODUCT(('Monthly Base'!$C$5:$BJ$5=4)*'Monthly Base'!$C$42:$BJ$42) -> 411689.18 | F26: =SUMPRODUCT(('Monthly Base'!$C$5:$BJ$5=5)*'Monthly Base'!$C$42:$BJ$42) -> 515788.1
A27: Gross margin % | B27: =IF(B25=0,0,B26/B25) -> 0.64607904 | C27: =IF(C25=0,0,C26/C25) -> 0.72536157 | D27: =IF(D25=0,0,D26/D25) -> 0.74311547 | E27: =IF(E25=0,0,E26/E25) -> 0.75406739 | F27: =IF(F25=0,0,F26/F25) -> 0.76227511
A28: Operating expenses ($) | B28: =SUMPRODUCT(('Monthly Base'!$C$5:$BJ$5=1)*'Monthly Base'!$C$52:$BJ$52) -> 168419.7 | C28: =SUMPRODUCT(('Monthly Base'!$C$5:$BJ$5=2)*'Monthly Base'!$C$52:$BJ$52) -> 274809.55 | D28: =SUMPRODUCT(('Monthly Base'!$C$5:$BJ$5=3)*'Monthly Base'!$C$52:$BJ$52) -> 451221.43 | E28: =SUMPRODUCT(('Monthly Base'!$C$5:$BJ$5=4)*'Monthly Base'!$C$52:$BJ$52) -> 522886.8 | F28: =SUMPRODUCT(('Monthly Base'!$C$5:$BJ$5=5)*'Monthly Base'!$C$52:$BJ$52) -> 622886.8
A29: EBITDA ($) | B29: =SUMPRODUCT(('Monthly Base'!$C$5:$BJ$5=1)*'Monthly Base'!$C$54:$BJ$54) -> -145381.15 | C29: =SUMPRODUCT(('Monthly Base'!$C$5:$BJ$5=2)*'Monthly Base'!$C$54:$BJ$54) -> -131399.12 | D29: =SUMPRODUCT(('Monthly Base'!$C$5:$BJ$5=3)*'Monthly Base'!$C$54:$BJ$54) -> -165527.81 | E29: =SUMPRODUCT(('Monthly Base'!$C$5:$BJ$5=4)*'Monthly Base'!$C$54:$BJ$54) -> -111197.62 | F29: =SUMPRODUCT(('Monthly Base'!$C$5:$BJ$5=5)*'Monthly Base'!$C$54:$BJ$54) -> -107098.7
A30: Cash, end of year ($) | B30: ='Monthly Base'!N55 -> -95381.145 | C30: ='Monthly Base'!Z55 -> -226780.26 | D30: ='Monthly Base'!AL55 -> -392308.07 | E30: ='Monthly Base'!AX55 -> -503505.69 | F30: ='Monthly Base'!BJ55 -> -610604.39
A31: Lowest cash balance in 5 years ($) | B31: =MIN('Monthly Base'!$C$55:$BJ$55) -> -610604.39
A32: Funding needed to stay above $0 ($) | B32: =MAX(0,-B31) -> 610604.39
A33: First month with positive EBITDA | B33: =IFERROR(INDEX('Monthly Base'!$C$4:$BJ$4,MATCH(TRUE(),INDEX('Monthly Base'!$C$54:$BJ$54>0,0),0)),"Not within 5 years") -> Not within 5 years
A34: Customer lifetime value ÷ acquisition cost (year 5) | B34: =IF('Monthly Base'!BJ31=0,0,'Monthly Base'!BJ33/'Monthly Base'!BJ31*F27/Assumptions!$D$26/Assumptions!$D$27) -> 4.1271646
A35: Share of addressable practices reached (year 5) | B35: =F23/Assumptions!$D$11 -> 0.025150381
A38: Aggressive scenario
A39: ($, US) | B39: Year 1 | C39: Year 2 | D39: Year 3 | E39: Year 4 | F39: Year 5
A40: Customers (end of year) | B40: ='Monthly Aggressive'!N31 -> 306.71705 | C40: ='Monthly Aggressive'!Z31 -> 804.80676 | D40: ='Monthly Aggressive'!AL31 -> 1252.6465 | E40: ='Monthly Aggressive'!AX31 -> 1614.2122 | F40: ='Monthly Aggressive'!BJ31 -> 1904.9658
A41: ARR, end of year ($) | B41: ='Monthly Aggressive'!N34 -> 190998.14 | C41: ='Monthly Aggressive'!Z34 -> 535848.71 | D41: ='Monthly Aggressive'!AL34 -> 889979.81 | E41: ='Monthly Aggressive'!AX34 -> 1212301.6 | F41: ='Monthly Aggressive'!BJ34 -> 1507498.8
A42: Revenue ($) | B42: =SUMPRODUCT(('Monthly Aggressive'!$C$5:$BJ$5=1)*'Monthly Aggressive'!$C$35:$BJ$35) -> 75720.624 | C42: =SUMPRODUCT(('Monthly Aggressive'!$C$5:$BJ$5=2)*'Monthly Aggressive'!$C$35:$BJ$35) -> 383239.47 | D42: =SUMPRODUCT(('Monthly Aggressive'!$C$5:$BJ$5=3)*'Monthly Aggressive'!$C$35:$BJ$35) -> 745149.73 | E42: =SUMPRODUCT(('Monthly Aggressive'!$C$5:$BJ$5=4)*'Monthly Aggressive'!$C$35:$BJ$35) -> 1089973.5 | F42: =SUMPRODUCT(('Monthly Aggressive'!$C$5:$BJ$5=5)*'Monthly Aggressive'!$C$35:$BJ$35) -> 1404210
A43: Gross profit ($) | B43: =SUMPRODUCT(('Monthly Aggressive'!$C$5:$BJ$5=1)*'Monthly Aggressive'!$C$42:$BJ$42) -> 52302.146 | C43: =SUMPRODUCT(('Monthly Aggressive'!$C$5:$BJ$5=2)*'Monthly Aggressive'!$C$42:$BJ$42) -> 282700.02 | D43: =SUMPRODUCT(('Monthly Aggressive'!$C$5:$BJ$5=3)*'Monthly Aggressive'!$C$42:$BJ$42) -> 563270.8 | E43: =SUMPRODUCT(('Monthly Aggressive'!$C$5:$BJ$5=4)*'Monthly Aggressive'!$C$42:$BJ$42) -> 838407.49 | F43: =SUMPRODUCT(('Monthly Aggressive'!$C$5:$BJ$5=5)*'Monthly Aggressive'!$C$42:$BJ$42) -> 1095527.7
A44: Gross margin % | B44: =IF(B42=0,0,B43/B42) -> 0.69072524 | C44: =IF(C42=0,0,C43/C42) -> 0.73765894 | D44: =IF(D42=0,0,D43/D42) -> 0.75591627 | E44: =IF(E42=0,0,E43/E42) -> 0.76919992 | F44: =IF(F42=0,0,F43/F42) -> 0.78017374
A45: Operating expenses ($) | B45: =SUMPRODUCT(('Monthly Aggressive'!$C$5:$BJ$5=1)*'Monthly Aggressive'!$C$52:$BJ$52) -> 209257.65 | C45: =SUMPRODUCT(('Monthly Aggressive'!$C$5:$BJ$5=2)*'Monthly Aggressive'!$C$52:$BJ$52) -> 324611.88 | D45: =SUMPRODUCT(('Monthly Aggressive'!$C$5:$BJ$5=3)*'Monthly Aggressive'!$C$52:$BJ$52) -> 503259.5 | E45: =SUMPRODUCT(('Monthly Aggressive'!$C$5:$BJ$5=4)*'Monthly Aggressive'!$C$52:$BJ$52) -> 573868.99 | F45: =SUMPRODUCT(('Monthly Aggressive'!$C$5:$BJ$5=5)*'Monthly Aggressive'!$C$52:$BJ$52) -> 673868.99
...

Sheet Assumptions
A1: InjuryCase — 5-year financial model: assumptions
A2: Blue = input you can change · yellow = key assumption · black = formula · green = link to another sheet. Monthly sheets and the Summary recalculate from these cells.
A4: Market segments (US practices that treat injury patients)
A5: Segment | B5: US practices | C5: % treating PI (est.) | D5: Addressable practices | E5: Launch month | F5: Monthly capture — Conservative | G5: Monthly capture — Base | H5: Monthly capture — Aggressive | I5: Price multiplier (plan mix vs. chiro) | J5: Source / basis
A6: Chiropractic clinics | B6: 66061 | C6: 0.35 | D6: =B6*C6 -> 23121.35 | E6: 1 | F6: 0.0006 | G6: 0.001 | H6: 0.0016 | I6: 1 | J6: Practices: IBISWorld, Chiropractors in the US, 2026 business count (ibisworld.com/united-states/number-of-businesses/chiropractors/1559). PI share is an estimate; NBCE Practice Analysis: ~14% of a typical chiropractor's patients come after a motor-vehicle accident.
A7: Physical therapy clinics | B7: 39000 | C7: 0.2 | D7: =B7*C7 -> 7800 | E7: 7 | F7: 0.0004 | G7: 0.0007 | H7: 0.0012 | I7: 1.1 | J7: Practices: ~38,000–40,000 outpatient PT clinics (APTA-based estimate, withorbital.com/data/largest-physical-therapy-chains-in-the-us). PI share estimated. Launch after PT-specific care-guide changes.
A8: Medical injury clinics (MD/DO, urgent care treating PI) | B8: 6000 | C8: 0.5 | D8: =B8*C8 -> 3000 | E8: 7 | F8: 0.0005 | G8: 0.0008 | H8: 0.0014 | I8: 1.15 | J8: No census found — 6,000 is a planning estimate. PI share estimated.
A9: Orthopedic practices | B9: 23142 | C9: 0.15 | D9: =B9*C9 -> 3471.3 | E9: 19 | F9: 0.0003 | G9: 0.0005 | H9: 0.0009 | I9: 1.4 | J9: Practices: Ciro, How many orthopedic practices are in the US (2024): 23,142 tracked. PI share estimated. Launch after a specialty module (procedures, surgical liens).
A10: Pain management practices | B10: 5000 | C10: 0.35 | D10: =B10*C10 -> 1750 | E10: 19 | F10: 0.0004 | G10: 0.0007 | H10: 0.0012 | I10: 1.4 | J10: Planning estimate: Definitive Healthcare lists 900+ pain-management groups (Dec 2025), most with several sites. PI share estimated. Launch after the specialty module.
A11: Total | B11: =SUM(B6:B10) -> 139203 | D11: =SUM(D6:D10) -> 39142.65 | J11: Monthly capture = share of a segment's addressable practices that become paying customers each month once marketing is fully ramped.
A13: Pricing (current plans)
A14: Plan | B14: Monthly price | C14: Plan mix | J14: Notes
A15: Silver | B15: 39 | C15: 0.4 | J15: Prices from app/saas.php (PLANS). Plan mix is an estimate for chiropractic clinics; segment price multipliers lift it for larger practices.
A16: Gold | B16: 59 | C16: 0.45
A17: Platinum | B17: 79 | C17: 0.15
A18: Plan mix check (must be 100%) | C18: =SUM(C15:C17) -> 1
A19: Customers on annual billing | B19: 0.3 | J19: Annual plans are charged 10 months for 12 (ANNUAL_MONTHS_CHARGED).
A20: Months charged on an annual plan | B20: 10
A21: List-price multiplier (1.0 = today's prices) | B21: 1 | J21: Pricing lever: try 1.5 or 2.0 to test higher prices.
A22: Blended revenue per chiro customer per month | B22: =SUMPRODUCT(B15:B17,C15:C17)*((1-B19)+B19*B20/12)*B21 -> 51.3
A24: Scenario levers
A25: Lever | C25: Conservative | D25: Base | E25: Aggressive | J25: Notes
A26: Monthly customer churn | C26: 0.035 | D26: 0.025 | E26: 0.018 | J26: Small-practice SaaS commonly loses 1.5–4% of customers a month.
A27: Acquisition cost per new paying customer | C27: 600 | D27: 450 | E27: 350 | J27: Ads, conferences, attorney and association referrals, sales time.
A28: Annual price increase | C28: 0 | D28: 0.03 | E28: 0.05 | J28: Applied at the start of each year after year 1.
A29: Months to reach full marketing ramp per segment | C29: 15 | D29: 12 | E29: 9 | J29: New customers grow linearly from launch to the full capture rate.
A31: Costs (all scenarios)
A32: Item | B32: Value | J32: Notes
A33: Card processing: % of revenue | B33: 0.029 | J33: Stripe standard US card pricing.
A34: Card processing: fee per charge | B34: 0.3 | J34: Stripe standard US card pricing.
A35: Hosting: fixed per month | B35: 250 | J35: AWS stack (deploy/aws): ~$40/mo minimum; budgeted higher for Multi-AZ database, backups and monitoring.
A36: Hosting: per customer per month | B36: 0.75 | J36: Storage, email (SES) and compute growth.
A37: Customers per support person | B37: 400 | J37: Estimate.
A38: Support salary, fully loaded (per year) | B38: 55000 | J38: Estimate.
A39: Engineer, fully loaded (per year) | B39: 140000 | J39: Estimate; can be contractors.
A40: Marketing: fixed per month | B40: 1500 | J40: Website, content, tools.
A41: Legal review: one-time in month 1 | B41: 20000 | J41: Attorney review of Terms, BAA and state rules (flagged as needed in the app).
A42: SOC 2 audit: one-time | B42: 30000 | J42: Often required by larger groups.
A43: SOC 2 audit: month | B43: 25
A44: Compliance and legal: per month | B44: 750 | J44: Ongoing counsel, HIPAA program.
...

Sheet Monthly Conservative
A1: Monthly projection — Conservative scenario
A2: All values are formulas driven by the Assumptions sheet.
A4: Month | C4: 1 | D4: 2 | E4: 3 | F4: 4 | G4: 5 | H4: 6 | I4: 7 | J4: 8 | K4: 9 | L4: 10 | M4: 11 | N4: 12 | O4: 13 | P4: 14 | Q4: 15 | R4: 16 | S4: 17 | T4: 18 | U4: 19 | V4: 20 | W4: 21 | X4: 22 | Y4: 23 | Z4: 24 | AA4: 25 | AB4: 26 | AC4: 27 | AD4: 28 | AE4: 29 | AF4: 30 | AG4: 31 | AH4: 32 | AI4: 33 | AJ4: 34 | AK4: 35 | AL4: 36 | AM4: 37 | AN4: 38 | AO4: 39 | AP4: 40 | AQ4: 41 | AR4: 42 | AS4: 43 | AT4: 44 | AU4: 45 | AV4: 46 | AW4: 47 | AX4: 48 | AY4: 49 | AZ4: 50 | BA4: 51 | BB4: 52 | BC4: 53 | BD4: 54 | BE4: 55 | BF4: 56 | BG4: 57 | BH4: 58 | BI4: 59 | BJ4: 60
A5: Year | C5: =INT((C4-1)/12)+1 -> 1 | D5: =INT((D4-1)/12)+1 -> 1 | E5: =INT((E4-1)/12)+1 -> 1 | F5: =INT((F4-1)/12)+1 -> 1 | G5: =INT((G4-1)/12)+1 -> 1 | H5: =INT((H4-1)/12)+1 -> 1 | I5: =INT((I4-1)/12)+1 -> 1 | J5: =INT((J4-1)/12)+1 -> 1 | ... BJ5: =INT((BJ4-1)/12)+1 -> 5
A6: Price factor (increases × list multiplier) | C6: =(1+Assumptions!$C$28)^(C5-1)*Assumptions!$B$21 -> 1 | D6: =(1+Assumptions!$C$28)^(D5-1)*Assumptions!$B$21 -> 1 | E6: =(1+Assumptions!$C$28)^(E5-1)*Assumptions!$B$21 -> 1 | F6: =(1+Assumptions!$C$28)^(F5-1)*Assumptions!$B$21 -> 1 | G6: =(1+Assumptions!$C$28)^(G5-1)*Assumptions!$B$21 -> 1 | H6: =(1+Assumptions!$C$28)^(H5-1)*Assumptions!$B$21 -> 1 | I6: =(1+Assumptions!$C$28)^(I5-1)*Assumptions!$B$21 -> 1 | J6: =(1+Assumptions!$C$28)^(J5-1)*Assumptions!$B$21 -> 1 | ... BJ6: =(1+Assumptions!$C$28)^(BJ5-1)*Assumptions!$B$21 -> 1
A8: Marketing ramp by segment
A9: Chiropractic clinics | C9: =IF(C4<Assumptions!$E$6,0,MIN(1,(C4-Assumptions!$E$6+1)/Assumptions!$C$29)) -> 0.066666667 | D9: =IF(D4<Assumptions!$E$6,0,MIN(1,(D4-Assumptions!$E$6+1)/Assumptions!$C$29)) -> 0.13333333 | E9: =IF(E4<Assumptions!$E$6,0,MIN(1,(E4-Assumptions!$E$6+1)/Assumptions!$C$29)) -> 0.2 | F9: =IF(F4<Assumptions!$E$6,0,MIN(1,(F4-Assumptions!$E$6+1)/Assumptions!$C$29)) -> 0.26666667 | G9: =IF(G4<Assumptions!$E$6,0,MIN(1,(G4-Assumptions!$E$6+1)/Assumptions!$C$29)) -> 0.33333333 | H9: =IF(H4<Assumptions!$E$6,0,MIN(1,(H4-Assumptions!$E$6+1)/Assumptions!$C$29)) -> 0.4 | I9: =IF(I4<Assumptions!$E$6,0,MIN(1,(I4-Assumptions!$E$6+1)/Assumptions!$C$29)) -> 0.46666667 | J9: =IF(J4<Assumptions!$E$6,0,MIN(1,(J4-Assumptions!$E$6+1)/Assumptions!$C$29)) -> 0.53333333 | ... BJ9: =IF(BJ4<Assumptions!$E$6,0,MIN(1,(BJ4-Assumptions!$E$6+1)/Assumptions!$C$29)) -> 1
A10: Physical therapy clinics | C10: =IF(C4<Assumptions!$E$7,0,MIN(1,(C4-Assumptions!$E$7+1)/Assumptions!$C$29)) -> 0 | D10: =IF(D4<Assumptions!$E$7,0,MIN(1,(D4-Assumptions!$E$7+1)/Assumptions!$C$29)) -> 0 | E10: =IF(E4<Assumptions!$E$7,0,MIN(1,(E4-Assumptions!$E$7+1)/Assumptions!$C$29)) -> 0 | F10: =IF(F4<Assumptions!$E$7,0,MIN(1,(F4-Assumptions!$E$7+1)/Assumptions!$C$29)) -> 0 | G10: =IF(G4<Assumptions!$E$7,0,MIN(1,(G4-Assumptions!$E$7+1)/Assumptions!$C$29)) -> 0 | H10: =IF(H4<Assumptions!$E$7,0,MIN(1,(H4-Assumptions!$E$7+1)/Assumptions!$C$29)) -> 0 | I10: =IF(I4<Assumptions!$E$7,0,MIN(1,(I4-Assumptions!$E$7+1)/Assumptions!$C$29)) -> 0.066666667 | J10: =IF(J4<Assumptions!$E$7,0,MIN(1,(J4-Assumptions!$E$7+1)/Assumptions!$C$29)) -> 0.13333333 | ... BJ10: =IF(BJ4<Assumptions!$E$7,0,MIN(1,(BJ4-Assumptions!$E$7+1)/Assumptions!$C$29)) -> 1
A11: Medical injury clinics (MD/DO, urgent care treating PI) | C11: =IF(C4<Assumptions!$E$8,0,MIN(1,(C4-Assumptions!$E$8+1)/Assumptions!$C$29)) -> 0 | D11: =IF(D4<Assumptions!$E$8,0,MIN(1,(D4-Assumptions!$E$8+1)/Assumptions!$C$29)) -> 0 | E11: =IF(E4<Assumptions!$E$8,0,MIN(1,(E4-Assumptions!$E$8+1)/Assumptions!$C$29)) -> 0 | F11: =IF(F4<Assumptions!$E$8,0,MIN(1,(F4-Assumptions!$E$8+1)/Assumptions!$C$29)) -> 0 | G11: =IF(G4<Assumptions!$E$8,0,MIN(1,(G4-Assumptions!$E$8+1)/Assumptions!$C$29)) -> 0 | H11: =IF(H4<Assumptions!$E$8,0,MIN(1,(H4-Assumptions!$E$8+1)/Assumptions!$C$29)) -> 0 | I11: =IF(I4<Assumptions!$E$8,0,MIN(1,(I4-Assumptions!$E$8+1)/Assumptions!$C$29)) -> 0.066666667 | J11: =IF(J4<Assumptions!$E$8,0,MIN(1,(J4-Assumptions!$E$8+1)/Assumptions!$C$29)) -> 0.13333333 | ... BJ11: =IF(BJ4<Assumptions!$E$8,0,MIN(1,(BJ4-Assumptions!$E$8+1)/Assumptions!$C$29)) -> 1
A12: Orthopedic practices | C12: =IF(C4<Assumptions!$E$9,0,MIN(1,(C4-Assumptions!$E$9+1)/Assumptions!$C$29)) -> 0 | D12: =IF(D4<Assumptions!$E$9,0,MIN(1,(D4-Assumptions!$E$9+1)/Assumptions!$C$29)) -> 0 | E12: =IF(E4<Assumptions!$E$9,0,MIN(1,(E4-Assumptions!$E$9+1)/Assumptions!$C$29)) -> 0 | F12: =IF(F4<Assumptions!$E$9,0,MIN(1,(F4-Assumptions!$E$9+1)/Assumptions!$C$29)) -> 0 | G12: =IF(G4<Assumptions!$E$9,0,MIN(1,(G4-Assumptions!$E$9+1)/Assumptions!$C$29)) -> 0 | H12: =IF(H4<Assumptions!$E$9,0,MIN(1,(H4-Assumptions!$E$9+1)/Assumptions!$C$29)) -> 0 | I12: =IF(I4<Assumptions!$E$9,0,MIN(1,(I4-Assumptions!$E$9+1)/Assumptions!$C$29)) -> 0 | J12: =IF(J4<Assumptions!$E$9,0,MIN(1,(J4-Assumptions!$E$9+1)/Assumptions!$C$29)) -> 0 | ... BJ12: =IF(BJ4<Assumptions!$E$9,0,MIN(1,(BJ4-Assumptions!$E$9+1)/Assumptions!$C$29)) -> 1
A13: Pain management practices | C13: =IF(C4<Assumptions!$E$10,0,MIN(1,(C4-Assumptions!$E$10+1)/Assumptions!$C$29)) -> 0 | D13: =IF(D4<Assumptions!$E$10,0,MIN(1,(D4-Assumptions!$E$10+1)/Assumptions!$C$29)) -> 0 | E13: =IF(E4<Assumptions!$E$10,0,MIN(1,(E4-Assumptions!$E$10+1)/Assumptions!$C$29)) -> 0 | F13: =IF(F4<Assumptions!$E$10,0,MIN(1,(F4-Assumptions!$E$10+1)/Assumptions!$C$29)) -> 0 | G13: =IF(G4<Assumptions!$E$10,0,MIN(1,(G4-Assumptions!$E$10+1)/Assumptions!$C$29)) -> 0 | H13: =IF(H4<Assumptions!$E$10,0,MIN(1,(H4-Assumptions!$E$10+1)/Assumptions!$C$29)) -> 0 | I13: =IF(I4<Assumptions!$E$10,0,MIN(1,(I4-Assumptions!$E$10+1)/Assumptions!$C$29)) -> 0 | J13: =IF(J4<Assumptions!$E$10,0,MIN(1,(J4-Assumptions!$E$10+1)/Assumptions!$C$29)) -> 0 | ... BJ13: =IF(BJ4<Assumptions!$E$10,0,MIN(1,(BJ4-Assumptions!$E$10+1)/Assumptions!$C$29)) -> 1
A15: New paying customers
A16: Chiropractic clinics | C16: =Assumptions!$D$6*Assumptions!$F$6*C9 -> 0.924854 | D16: =Assumptions!$D$6*Assumptions!$F$6*D9 -> 1.849708 | E16: =Assumptions!$D$6*Assumptions!$F$6*E9 -> 2.774562 | F16: =Assumptions!$D$6*Assumptions!$F$6*F9 -> 3.699416 | G16: =Assumptions!$D$6*Assumptions!$F$6*G9 -> 4.62427 | H16: =Assumptions!$D$6*Assumptions!$F$6*H9 -> 5.549124 | I16: =Assumptions!$D$6*Assumptions!$F$6*I9 -> 6.473978 | J16: =Assumptions!$D$6*Assumptions!$F$6*J9 -> 7.398832 | ... BJ16: =Assumptions!$D$6*Assumptions!$F$6*BJ9 -> 13.87281
A17: Physical therapy clinics | C17: =Assumptions!$D$7*Assumptions!$F$7*C10 -> 0 | D17: =Assumptions!$D$7*Assumptions!$F$7*D10 -> 0 | E17: =Assumptions!$D$7*Assumptions!$F$7*E10 -> 0 | F17: =Assumptions!$D$7*Assumptions!$F$7*F10 -> 0 | G17: =Assumptions!$D$7*Assumptions!$F$7*G10 -> 0 | H17: =Assumptions!$D$7*Assumptions!$F$7*H10 -> 0 | I17: =Assumptions!$D$7*Assumptions!$F$7*I10 -> 0.208 | J17: =Assumptions!$D$7*Assumptions!$F$7*J10 -> 0.416 | ... BJ17: =Assumptions!$D$7*Assumptions!$F$7*BJ10 -> 3.12
A18: Medical injury clinics (MD/DO, urgent care treating PI) | C18: =Assumptions!$D$8*Assumptions!$F$8*C11 -> 0 | D18: =Assumptions!$D$8*Assumptions!$F$8*D11 -> 0 | E18: =Assumptions!$D$8*Assumptions!$F$8*E11 -> 0 | F18: =Assumptions!$D$8*Assumptions!$F$8*F11 -> 0 | G18: =Assumptions!$D$8*Assumptions!$F$8*G11 -> 0 | H18: =Assumptions!$D$8*Assumptions!$F$8*H11 -> 0 | I18: =Assumptions!$D$8*Assumptions!$F$8*I11 -> 0.1 | J18: =Assumptions!$D$8*Assumptions!$F$8*J11 -> 0.2 | ... BJ18: =Assumptions!$D$8*Assumptions!$F$8*BJ11 -> 1.5
A19: Orthopedic practices | C19: =Assumptions!$D$9*Assumptions!$F$9*C12 -> 0 | D19: =Assumptions!$D$9*Assumptions!$F$9*D12 -> 0 | E19: =Assumptions!$D$9*Assumptions!$F$9*E12 -> 0 | F19: =Assumptions!$D$9*Assumptions!$F$9*F12 -> 0 | G19: =Assumptions!$D$9*Assumptions!$F$9*G12 -> 0 | H19: =Assumptions!$D$9*Assumptions!$F$9*H12 -> 0 | I19: =Assumptions!$D$9*Assumptions!$F$9*I12 -> 0 | J19: =Assumptions!$D$9*Assumptions!$F$9*J12 -> 0 | ... BJ19: =Assumptions!$D$9*Assumptions!$F$9*BJ12 -> 1.04139
A20: Pain management practices | C20: =Assumptions!$D$10*Assumptions!$F$10*C13 -> 0 | D20: =Assumptions!$D$10*Assumptions!$F$10*D13 -> 0 | E20: =Assumptions!$D$10*Assumptions!$F$10*E13 -> 0 | F20: =Assumptions!$D$10*Assumptions!$F$10*F13 -> 0 | G20: =Assumptions!$D$10*Assumptions!$F$10*G13 -> 0 | H20: =Assumptions!$D$10*Assumptions!$F$10*H13 -> 0 | I20: =Assumptions!$D$10*Assumptions!$F$10*I13 -> 0 | J20: =Assumptions!$D$10*Assumptions!$F$10*J13 -> 0 | ... BJ20: =Assumptions!$D$10*Assumptions!$F$10*BJ13 -> 0.7
A22: Active customers (end of month)
A23: Chiropractic clinics | C23: =C16 -> 0.924854 | D23: =C23*(1-Assumptions!$C$26)+D16 -> 2.7421921 | E23: =D23*(1-Assumptions!$C$26)+E16 -> 5.4207774 | F23: =E23*(1-Assumptions!$C$26)+F16 -> 8.9304662 | G23: =F23*(1-Assumptions!$C$26)+G16 -> 13.24217 | H23: =G23*(1-Assumptions!$C$26)+H16 -> 18.327818 | I23: =H23*(1-Assumptions!$C$26)+I16 -> 24.160322 | J23: =I23*(1-Assumptions!$C$26)+J16 -> 30.713543 | K23: =J23*(1-Assumptions!$C$26)+K16 -> 37.962255 | ... BJ23: =BI23*(1-Assumptions!$C$26)+BJ16 -> 335.66767
A24: Physical therapy clinics | C24: =C17 -> 0 | D24: =C24*(1-Assumptions!$C$26)+D17 -> 0 | E24: =D24*(1-Assumptions!$C$26)+E17 -> 0 | F24: =E24*(1-Assumptions!$C$26)+F17 -> 0 | G24: =F24*(1-Assumptions!$C$26)+G17 -> 0 | H24: =G24*(1-Assumptions!$C$26)+H17 -> 0 | I24: =H24*(1-Assumptions!$C$26)+I17 -> 0.208 | J24: =I24*(1-Assumptions!$C$26)+J17 -> 0.61672 | K24: =J24*(1-Assumptions!$C$26)+K17 -> 1.2191348 | ... BJ24: =BI24*(1-Assumptions!$C$26)+BJ17 -> 72.23833
A25: Medical injury clinics (MD/DO, urgent care treating PI) | C25: =C18 -> 0 | D25: =C25*(1-Assumptions!$C$26)+D18 -> 0 | E25: =D25*(1-Assumptions!$C$26)+E18 -> 0 | F25: =E25*(1-Assumptions!$C$26)+F18 -> 0 | G25: =F25*(1-Assumptions!$C$26)+G18 -> 0 | H25: =G25*(1-Assumptions!$C$26)+H18 -> 0 | I25: =H25*(1-Assumptions!$C$26)+I18 -> 0.1 | J25: =I25*(1-Assumptions!$C$26)+J18 -> 0.2965 | K25: =J25*(1-Assumptions!$C$26)+K18 -> 0.5861225 | ... BJ25: =BI25*(1-Assumptions!$C$26)+BJ18 -> 34.729967
A26: Orthopedic practices | C26: =C19 -> 0 | D26: =C26*(1-Assumptions!$C$26)+D19 -> 0 | E26: =D26*(1-Assumptions!$C$26)+E19 -> 0 | F26: =E26*(1-Assumptions!$C$26)+F19 -> 0 | G26: =F26*(1-Assumptions!$C$26)+G19 -> 0 | H26: =G26*(1-Assumptions!$C$26)+H19 -> 0 | I26: =H26*(1-Assumptions!$C$26)+I19 -> 0 | J26: =I26*(1-Assumptions!$C$26)+J19 -> 0 | K26: =J26*(1-Assumptions!$C$26)+K19 -> 0 | ... BJ26: =BI26*(1-Assumptions!$C$26)+BJ19 -> 21.10165
A27: Pain management practices | C27: =C20 -> 0 | D27: =C27*(1-Assumptions!$C$26)+D20 -> 0 | E27: =D27*(1-Assumptions!$C$26)+E20 -> 0 | F27: =E27*(1-Assumptions!$C$26)+F20 -> 0 | G27: =F27*(1-Assumptions!$C$26)+G20 -> 0 | H27: =G27*(1-Assumptions!$C$26)+H20 -> 0 | I27: =H27*(1-Assumptions!$C$26)+I20 -> 0 | J27: =I27*(1-Assumptions!$C$26)+J20 -> 0 | K27: =J27*(1-Assumptions!$C$26)+K20 -> 0 | ... BJ27: =BI27*(1-Assumptions!$C$26)+BJ20 -> 14.184076
A29: Total new customers | C29: =SUM(C16:C20) -> 0.924854 | D29: =SUM(D16:D20) -> 1.849708 | E29: =SUM(E16:E20) -> 2.774562 | F29: =SUM(F16:F20) -> 3.699416 | G29: =SUM(G16:G20) -> 4.62427 | H29: =SUM(H16:H20) -> 5.549124 | I29: =SUM(I16:I20) -> 6.781978 | J29: =SUM(J16:J20) -> 8.014832 | ... BJ29: =SUM(BJ16:BJ20) -> 20.2342
A30: Customers lost (churn) | C30: 0 | D30: =C31*Assumptions!$C$26 -> 0.03236989 | E30: =D31*Assumptions!$C$26 -> 0.095976724 | F30: =E31*Assumptions!$C$26 -> 0.18972721 | G30: =F31*Assumptions!$C$26 -> 0.31256632 | H30: =G31*Assumptions!$C$26 -> 0.46347595 | I30: =H31*Assumptions!$C$26 -> 0.64147363 | J30: =I31*Assumptions!$C$26 -> 0.85639128 | K30: =J31*Assumptions!$C$26 -> 1.1069367 | ... BJ30: =BI31*Assumptions!$C$26 -> 16.600065
A31: Total active customers | C31: =SUM(C23:C27) -> 0.924854 | D31: =SUM(D23:D27) -> 2.7421921 | E31: =SUM(E23:E27) -> 5.4207774 | F31: =SUM(F23:F27) -> 8.9304662 | G31: =SUM(G23:G27) -> 13.24217 | H31: =SUM(H23:H27) -> 18.327818 | I31: =SUM(I23:I27) -> 24.468322 | J31: =SUM(J23:J27) -> 31.626763 | ... BJ31: =SUM(BJ23:BJ27) -> 477.92169
A33: MRR ($) | C33: =SUMPRODUCT(C23:C27,Assumptions!$I$6:$I$10)*Assumptions!$B$22/Assumptions!$B$21*C6 -> 47.44501 | D33: =SUMPRODUCT(D23:D27,Assumptions!$I$6:$I$10)*Assumptions!$B$22/Assumptions!$B$21*D6 -> 140.67446 | E33: =SUMPRODUCT(E23:E27,Assumptions!$I$6:$I$10)*Assumptions!$B$22/Assumptions!$B$21*E6 -> 278.08588 | F33: =SUMPRODUCT(F23:F27,Assumptions!$I$6:$I$10)*Assumptions!$B$22/Assumptions!$B$21*F6 -> 458.13291 | G33: =SUMPRODUCT(G23:G27,Assumptions!$I$6:$I$10)*Assumptions!$B$22/Assumptions!$B$21*G6 -> 679.32331 | H33: =SUMPRODUCT(H23:H27,Assumptions!$I$6:$I$10)*Assumptions!$B$22/Assumptions!$B$21*H6 -> 940.21706 | I33: =SUMPRODUCT(I23:I27,Assumptions!$I$6:$I$10)*Assumptions!$B$22/Assumptions!$B$21*I6 -> 1257.0615 | J33: =SUMPRODUCT(J23:J27,Assumptions!$I$6:$I$10)*Assumptions!$B$22/Assumptions!$B$21*J6 -> 1627.8983 | ... BJ33: =SUMPRODUCT(BJ23:BJ27,Assumptions!$I$6:$I$10)*Assumptions!$B$22/Assumptions!$B$21*BJ6 -> 25879.276
A34: ARR ($) | C34: =C33*12 -> 569.34012 | D34: =D33*12 -> 1688.0935 | E34: =E33*12 -> 3337.0306 | F34: =F33*12 -> 5497.595 | G34: =G33*12 -> 8151.8798 | H34: =H33*12 -> 11282.605 | I34: =I33*12 -> 15084.738 | J34: =J33*12 -> 19534.779 | ... BJ34: =BJ33*12 -> 310551.31
A35: Revenue ($) | C35: =C33 -> 47.44501 | D35: =D33 -> 140.67446 | E35: =E33 -> 278.08588 | F35: =F33 -> 458.13291 | G35: =G33 -> 679.32331 | H35: =H33 -> 940.21706 | I35: =I33 -> 1257.0615 | J35: =J33 -> 1627.8983 | ... BJ35: =BJ33 -> 25879.276
A37: Cost of revenue
A38: Card processing | C38: =C35*Assumptions!$B$33+C31*((1-Assumptions!$B$19)+Assumptions!$B$19/12)*Assumptions!$B$34 -> 1.577061 | D38: =D35*Assumptions!$B$33+D31*((1-Assumptions!$B$19)+Assumptions!$B$19/12)*Assumptions!$B$34 -> 4.675986 | E38: =E35*Assumptions!$B$33+E31*((1-Assumptions!$B$19)+Assumptions!$B$19/12)*Assumptions!$B$34 -> 9.2435096 | F38: =F35*Assumptions!$B$33+F31*((1-Assumptions!$B$19)+Assumptions!$B$19/12)*Assumptions!$B$34 -> 15.228231 | G38: =G35*Assumptions!$B$33+G31*((1-Assumptions!$B$19)+Assumptions!$B$19/12)*Assumptions!$B$34 -> 22.580548 | H38: =H35*Assumptions!$B$33+H31*((1-Assumptions!$B$19)+Assumptions!$B$19/12)*Assumptions!$B$34 -> 31.252595 | I38: =I35*Assumptions!$B$33+I31*((1-Assumptions!$B$19)+Assumptions!$B$19/12)*Assumptions!$B$34 -> 41.776643 | J38: =J35*Assumptions!$B$33+J31*((1-Assumptions!$B$19)+Assumptions!$B$19/12)*Assumptions!$B$34 -> 54.087871 | ... BJ38: =BJ35*Assumptions!$B$33+BJ31*((1-Assumptions!$B$19)+Assumptions!$B$19/12)*Assumptions!$B$34 -> 854.44696
A39: Hosting | C39: =Assumptions!$B$35+Assumptions!$B$36*C31 -> 250.69364 | D39: =Assumptions!$B$35+Assumptions!$B$36*D31 -> 252.05664 | E39: =Assumptions!$B$35+Assumptions!$B$36*E31 -> 254.06558 | F39: =Assumptions!$B$35+Assumptions!$B$36*F31 -> 256.69785 | G39: =Assumptions!$B$35+Assumptions!$B$36*G31 -> 259.93163 | H39: =Assumptions!$B$35+Assumptions!$B$36*H31 -> 263.74586 | I39: =Assumptions!$B$35+Assumptions!$B$36*I31 -> 268.35124 | J39: =Assumptions!$B$35+Assumptions!$B$36*J31 -> 273.72007 | ... BJ39: =Assumptions!$B$35+Assumptions!$B$36*BJ31 -> 608.44127
A40: Customer support | C40: =C31/Assumptions!$B$37*Assumptions!$B$38/12 -> 10.597285 | D40: =D31/Assumptions!$B$37*Assumptions!$B$38/12 -> 31.420951 | E40: =E31/Assumptions!$B$37*Assumptions!$B$38/12 -> 62.113074 | F40: =F31/Assumptions!$B$37*Assumptions!$B$38/12 -> 102.32826 | G40: =G31/Assumptions!$B$37*Assumptions!$B$38/12 -> 151.7332 | H40: =H31/Assumptions!$B$37*Assumptions!$B$38/12 -> 210.00625 | I40: =I31/Assumptions!$B$37*Assumptions!$B$38/12 -> 280.36619 | J40: =J31/Assumptions!$B$37*Assumptions!$B$38/12 -> 362.38999 | ... BJ40: =BJ31/Assumptions!$B$37*Assumptions!$B$38/12 -> 5476.1861
A41: Total cost of revenue | C41: =SUM(C38:C40) -> 262.86799 | D41: =SUM(D38:D40) -> 288.15358 | E41: =SUM(E38:E40) -> 325.42217 | F41: =SUM(F38:F40) -> 374.25434 | G41: =SUM(G38:G40) -> 434.24537 | H41: =SUM(H38:H40) -> 505.00471 | I41: =SUM(I38:I40) -> 590.49408 | J41: =SUM(J38:J40) -> 690.19794 | ... BJ41: =SUM(BJ38:BJ40) -> 6939.0743
A42: Gross profit | C42: =C35-C41 -> -215.42298 | D42: =D35-D41 -> -147.47913 | E42: =E35-E41 -> -47.336287 | F42: =F35-F41 -> 83.878576 | G42: =G35-G41 -> 245.07794 | H42: =H35-H41 -> 435.21235 | I42: =I35-I41 -> 666.5674 | J42: =J35-J41 -> 937.70035 | ... BJ42: =BJ35-BJ41 -> 18940.201
A43: Gross margin % | C43: =IF(C35=0,0,C42/C35) -> -4.540477 | D43: =IF(D35=0,0,D42/D35) -> -1.0483718 | E43: =IF(E35=0,0,E42/E35) -> -0.17022183 | F43: =IF(F35=0,0,F42/F35) -> 0.18308786 | G43: =IF(G35=0,0,G42/G35) -> 0.36076775 | H43: =IF(H35=0,0,H42/H35) -> 0.46288498 | I43: =IF(I35=0,0,I42/I35) -> 0.53025839 | J43: =IF(J35=0,0,J42/J35) -> 0.576019 | ... BJ43: =IF(BJ35=0,0,BJ42/BJ35) -> 0.73186752
A45: Operating expenses
A46: Engineering | C46: =INDEX(Assumptions!$B$50:$F$50,C5)*Assumptions!$B$39/12 -> 2916.6667 | D46: =INDEX(Assumptions!$B$50:$F$50,D5)*Assumptions!$B$39/12 -> 2916.6667 | E46: =INDEX(Assumptions!$B$50:$F$50,E5)*Assumptions!$B$39/12 -> 2916.6667 | F46: =INDEX(Assumptions!$B$50:$F$50,F5)*Assumptions!$B$39/12 -> 2916.6667 | G46: =INDEX(Assumptions!$B$50:$F$50,G5)*Assumptions!$B$39/12 -> 2916.6667 | H46: =INDEX(Assumptions!$B$50:$F$50,H5)*Assumptions!$B$39/12 -> 2916.6667 | I46: =INDEX(Assumptions!$B$50:$F$50,I5)*Assumptions!$B$39/12 -> 2916.6667 | J46: =INDEX(Assumptions!$B$50:$F$50,J5)*Assumptions!$B$39/12 -> 2916.6667 | ... BJ46: =INDEX(Assumptions!$B$50:$F$50,BJ5)*Assumptions!$B$39/12 -> 23333.333
A47: Founder salary | C47: =INDEX(Assumptions!$B$51:$F$51,C5)/12 -> 0 | D47: =INDEX(Assumptions!$B$51:$F$51,D5)/12 -> 0 | E47: =INDEX(Assumptions!$B$51:$F$51,E5)/12 -> 0 | F47: =INDEX(Assumptions!$B$51:$F$51,F5)/12 -> 0 | G47: =INDEX(Assumptions!$B$51:$F$51,G5)/12 -> 0 | H47: =INDEX(Assumptions!$B$51:$F$51,H5)/12 -> 0 | I47: =INDEX(Assumptions!$B$51:$F$51,I5)/12 -> 0 | J47: =INDEX(Assumptions!$B$51:$F$51,J5)/12 -> 0 | ... BJ47: =INDEX(Assumptions!$B$51:$F$51,BJ5)/12 -> 10000
A48: Sales & marketing | C48: =C29*Assumptions!$C$27+Assumptions!$B$40 -> 2054.9124 | D48: =D29*Assumptions!$C$27+Assumptions!$B$40 -> 2609.8248 | E48: =E29*Assumptions!$C$27+Assumptions!$B$40 -> 3164.7372 | F48: =F29*Assumptions!$C$27+Assumptions!$B$40 -> 3719.6496 | G48: =G29*Assumptions!$C$27+Assumptions!$B$40 -> 4274.562 | H48: =H29*Assumptions!$C$27+Assumptions!$B$40 -> 4829.4744 | I48: =I29*Assumptions!$C$27+Assumptions!$B$40 -> 5569.1868 | J48: =J29*Assumptions!$C$27+Assumptions!$B$40 -> 6308.8992 | ... BJ48: =BJ29*Assumptions!$C$27+Assumptions!$B$40 -> 13640.52
...

Sheet Monthly Base
A1: Monthly projection — Base scenario
A2: All values are formulas driven by the Assumptions sheet.
A4: Month | C4: 1 | D4: 2 | E4: 3 | F4: 4 | G4: 5 | H4: 6 | I4: 7 | J4: 8 | K4: 9 | L4: 10 | M4: 11 | N4: 12 | O4: 13 | P4: 14 | Q4: 15 | R4: 16 | S4: 17 | T4: 18 | U4: 19 | V4: 20 | W4: 21 | X4: 22 | Y4: 23 | Z4: 24 | AA4: 25 | AB4: 26 | AC4: 27 | AD4: 28 | AE4: 29 | AF4: 30 | AG4: 31 | AH4: 32 | AI4: 33 | AJ4: 34 | AK4: 35 | AL4: 36 | AM4: 37 | AN4: 38 | AO4: 39 | AP4: 40 | AQ4: 41 | AR4: 42 | AS4: 43 | AT4: 44 | AU4: 45 | AV4: 46 | AW4: 47 | AX4: 48 | AY4: 49 | AZ4: 50 | BA4: 51 | BB4: 52 | BC4: 53 | BD4: 54 | BE4: 55 | BF4: 56 | BG4: 57 | BH4: 58 | BI4: 59 | BJ4: 60
A5: Year | C5: =INT((C4-1)/12)+1 -> 1 | D5: =INT((D4-1)/12)+1 -> 1 | E5: =INT((E4-1)/12)+1 -> 1 | F5: =INT((F4-1)/12)+1 -> 1 | G5: =INT((G4-1)/12)+1 -> 1 | H5: =INT((H4-1)/12)+1 -> 1 | I5: =INT((I4-1)/12)+1 -> 1 | J5: =INT((J4-1)/12)+1 -> 1 | ... BJ5: =INT((BJ4-1)/12)+1 -> 5
A6: Price factor (increases × list multiplier) | C6: =(1+Assumptions!$D$28)^(C5-1)*Assumptions!$B$21 -> 1 | D6: =(1+Assumptions!$D$28)^(D5-1)*Assumptions!$B$21 -> 1 | E6: =(1+Assumptions!$D$28)^(E5-1)*Assumptions!$B$21 -> 1 | F6: =(1+Assumptions!$D$28)^(F5-1)*Assumptions!$B$21 -> 1 | G6: =(1+Assumptions!$D$28)^(G5-1)*Assumptions!$B$21 -> 1 | H6: =(1+Assumptions!$D$28)^(H5-1)*Assumptions!$B$21 -> 1 | I6: =(1+Assumptions!$D$28)^(I5-1)*Assumptions!$B$21 -> 1 | J6: =(1+Assumptions!$D$28)^(J5-1)*Assumptions!$B$21 -> 1 | ... BJ6: =(1+Assumptions!$D$28)^(BJ5-1)*Assumptions!$B$21 -> 1.1255088
A8: Marketing ramp by segment
A9: Chiropractic clinics | C9: =IF(C4<Assumptions!$E$6,0,MIN(1,(C4-Assumptions!$E$6+1)/Assumptions!$D$29)) -> 0.083333333 | D9: =IF(D4<Assumptions!$E$6,0,MIN(1,(D4-Assumptions!$E$6+1)/Assumptions!$D$29)) -> 0.16666667 | E9: =IF(E4<Assumptions!$E$6,0,MIN(1,(E4-Assumptions!$E$6+1)/Assumptions!$D$29)) -> 0.25 | F9: =IF(F4<Assumptions!$E$6,0,MIN(1,(F4-Assumptions!$E$6+1)/Assumptions!$D$29)) -> 0.33333333 | G9: =IF(G4<Assumptions!$E$6,0,MIN(1,(G4-Assumptions!$E$6+1)/Assumptions!$D$29)) -> 0.41666667 | H9: =IF(H4<Assumptions!$E$6,0,MIN(1,(H4-Assumptions!$E$6+1)/Assumptions!$D$29)) -> 0.5 | I9: =IF(I4<Assumptions!$E$6,0,MIN(1,(I4-Assumptions!$E$6+1)/Assumptions!$D$29)) -> 0.58333333 | J9: =IF(J4<Assumptions!$E$6,0,MIN(1,(J4-Assumptions!$E$6+1)/Assumptions!$D$29)) -> 0.66666667 | ... BJ9: =IF(BJ4<Assumptions!$E$6,0,MIN(1,(BJ4-Assumptions!$E$6+1)/Assumptions!$D$29)) -> 1
A10: Physical therapy clinics | C10: =IF(C4<Assumptions!$E$7,0,MIN(1,(C4-Assumptions!$E$7+1)/Assumptions!$D$29)) -> 0 | D10: =IF(D4<Assumptions!$E$7,0,MIN(1,(D4-Assumptions!$E$7+1)/Assumptions!$D$29)) -> 0 | E10: =IF(E4<Assumptions!$E$7,0,MIN(1,(E4-Assumptions!$E$7+1)/Assumptions!$D$29)) -> 0 | F10: =IF(F4<Assumptions!$E$7,0,MIN(1,(F4-Assumptions!$E$7+1)/Assumptions!$D$29)) -> 0 | G10: =IF(G4<Assumptions!$E$7,0,MIN(1,(G4-Assumptions!$E$7+1)/Assumptions!$D$29)) -> 0 | H10: =IF(H4<Assumptions!$E$7,0,MIN(1,(H4-Assumptions!$E$7+1)/Assumptions!$D$29)) -> 0 | I10: =IF(I4<Assumptions!$E$7,0,MIN(1,(I4-Assumptions!$E$7+1)/Assumptions!$D$29)) -> 0.083333333 | J10: =IF(J4<Assumptions!$E$7,0,MIN(1,(J4-Assumptions!$E$7+1)/Assumptions!$D$29)) -> 0.16666667 | ... BJ10: =IF(BJ4<Assumptions!$E$7,0,MIN(1,(BJ4-Assumptions!$E$7+1)/Assumptions!$D$29)) -> 1
A11: Medical injury clinics (MD/DO, urgent care treating PI) | C11: =IF(C4<Assumptions!$E$8,0,MIN(1,(C4-Assumptions!$E$8+1)/Assumptions!$D$29)) -> 0 | D11: =IF(D4<Assumptions!$E$8,0,MIN(1,(D4-Assumptions!$E$8+1)/Assumptions!$D$29)) -> 0 | E11: =IF(E4<Assumptions!$E$8,0,MIN(1,(E4-Assumptions!$E$8+1)/Assumptions!$D$29)) -> 0 | F11: =IF(F4<Assumptions!$E$8,0,MIN(1,(F4-Assumptions!$E$8+1)/Assumptions!$D$29)) -> 0 | G11: =IF(G4<Assumptions!$E$8,0,MIN(1,(G4-Assumptions!$E$8+1)/Assumptions!$D$29)) -> 0 | H11: =IF(H4<Assumptions!$E$8,0,MIN(1,(H4-Assumptions!$E$8+1)/Assumptions!$D$29)) -> 0 | I11: =IF(I4<Assumptions!$E$8,0,MIN(1,(I4-Assumptions!$E$8+1)/Assumptions!$D$29)) -> 0.083333333 | J11: =IF(J4<Assumptions!$E$8,0,MIN(1,(J4-Assumptions!$E$8+1)/Assumptions!$D$29)) -> 0.16666667 | ... BJ11: =IF(BJ4<Assumptions!$E$8,0,MIN(1,(BJ4-Assumptions!$E$8+1)/Assumptions!$D$29)) -> 1
A12: Orthopedic practices | C12: =IF(C4<Assumptions!$E$9,0,MIN(1,(C4-Assumptions!$E$9+1)/Assumptions!$D$29)) -> 0 | D12: =IF(D4<Assumptions!$E$9,0,MIN(1,(D4-Assumptions!$E$9+1)/Assumptions!$D$29)) -> 0 | E12: =IF(E4<Assumptions!$E$9,0,MIN(1,(E4-Assumptions!$E$9+1)/Assumptions!$D$29)) -> 0 | F12: =IF(F4<Assumptions!$E$9,0,MIN(1,(F4-Assumptions!$E$9+1)/Assumptions!$D$29)) -> 0 | G12: =IF(G4<Assumptions!$E$9,0,MIN(1,(G4-Assumptions!$E$9+1)/Assumptions!$D$29)) -> 0 | H12: =IF(H4<Assumptions!$E$9,0,MIN(1,(H4-Assumptions!$E$9+1)/Assumptions!$D$29)) -> 0 | I12: =IF(I4<Assumptions!$E$9,0,MIN(1,(I4-Assumptions!$E$9+1)/Assumptions!$D$29)) -> 0 | J12: =IF(J4<Assumptions!$E$9,0,MIN(1,(J4-Assumptions!$E$9+1)/Assumptions!$D$29)) -> 0 | ... BJ12: =IF(BJ4<Assumptions!$E$9,0,MIN(1,(BJ4-Assumptions!$E$9+1)/Assumptions!$D$29)) -> 1
A13: Pain management practices | C13: =IF(C4<Assumptions!$E$10,0,MIN(1,(C4-Assumptions!$E$10+1)/Assumptions!$D$29)) -> 0 | D13: =IF(D4<Assumptions!$E$10,0,MIN(1,(D4-Assumptions!$E$10+1)/Assumptions!$D$29)) -> 0 | E13: =IF(E4<Assumptions!$E$10,0,MIN(1,(E4-Assumptions!$E$10+1)/Assumptions!$D$29)) -> 0 | F13: =IF(F4<Assumptions!$E$10,0,MIN(1,(F4-Assumptions!$E$10+1)/Assumptions!$D$29)) -> 0 | G13: =IF(G4<Assumptions!$E$10,0,MIN(1,(G4-Assumptions!$E$10+1)/Assumptions!$D$29)) -> 0 | H13: =IF(H4<Assumptions!$E$10,0,MIN(1,(H4-Assumptions!$E$10+1)/Assumptions!$D$29)) -> 0 | I13: =IF(I4<Assumptions!$E$10,0,MIN(1,(I4-Assumptions!$E$10+1)/Assumptions!$D$29)) -> 0 | J13: =IF(J4<Assumptions!$E$10,0,MIN(1,(J4-Assumptions!$E$10+1)/Assumptions!$D$29)) -> 0 | ... BJ13: =IF(BJ4<Assumptions!$E$10,0,MIN(1,(BJ4-Assumptions!$E$10+1)/Assumptions!$D$29)) -> 1
A15: New paying customers
A16: Chiropractic clinics | C16: =Assumptions!$D$6*Assumptions!$G$6*C9 -> 1.9267792 | D16: =Assumptions!$D$6*Assumptions!$G$6*D9 -> 3.8535583 | E16: =Assumptions!$D$6*Assumptions!$G$6*E9 -> 5.7803375 | F16: =Assumptions!$D$6*Assumptions!$G$6*F9 -> 7.7071167 | G16: =Assumptions!$D$6*Assumptions!$G$6*G9 -> 9.6338958 | H16: =Assumptions!$D$6*Assumptions!$G$6*H9 -> 11.560675 | I16: =Assumptions!$D$6*Assumptions!$G$6*I9 -> 13.487454 | J16: =Assumptions!$D$6*Assumptions!$G$6*J9 -> 15.414233 | ... BJ16: =Assumptions!$D$6*Assumptions!$G$6*BJ9 -> 23.12135
A17: Physical therapy clinics | C17: =Assumptions!$D$7*Assumptions!$G$7*C10 -> 0 | D17: =Assumptions!$D$7*Assumptions!$G$7*D10 -> 0 | E17: =Assumptions!$D$7*Assumptions!$G$7*E10 -> 0 | F17: =Assumptions!$D$7*Assumptions!$G$7*F10 -> 0 | G17: =Assumptions!$D$7*Assumptions!$G$7*G10 -> 0 | H17: =Assumptions!$D$7*Assumptions!$G$7*H10 -> 0 | I17: =Assumptions!$D$7*Assumptions!$G$7*I10 -> 0.455 | J17: =Assumptions!$D$7*Assumptions!$G$7*J10 -> 0.91 | ... BJ17: =Assumptions!$D$7*Assumptions!$G$7*BJ10 -> 5.46
A18: Medical injury clinics (MD/DO, urgent care treating PI) | C18: =Assumptions!$D$8*Assumptions!$G$8*C11 -> 0 | D18: =Assumptions!$D$8*Assumptions!$G$8*D11 -> 0 | E18: =Assumptions!$D$8*Assumptions!$G$8*E11 -> 0 | F18: =Assumptions!$D$8*Assumptions!$G$8*F11 -> 0 | G18: =Assumptions!$D$8*Assumptions!$G$8*G11 -> 0 | H18: =Assumptions!$D$8*Assumptions!$G$8*H11 -> 0 | I18: =Assumptions!$D$8*Assumptions!$G$8*I11 -> 0.2 | J18: =Assumptions!$D$8*Assumptions!$G$8*J11 -> 0.4 | ... BJ18: =Assumptions!$D$8*Assumptions!$G$8*BJ11 -> 2.4
A19: Orthopedic practices | C19: =Assumptions!$D$9*Assumptions!$G$9*C12 -> 0 | D19: =Assumptions!$D$9*Assumptions!$G$9*D12 -> 0 | E19: =Assumptions!$D$9*Assumptions!$G$9*E12 -> 0 | F19: =Assumptions!$D$9*Assumptions!$G$9*F12 -> 0 | G19: =Assumptions!$D$9*Assumptions!$G$9*G12 -> 0 | H19: =Assumptions!$D$9*Assumptions!$G$9*H12 -> 0 | I19: =Assumptions!$D$9*Assumptions!$G$9*I12 -> 0 | J19: =Assumptions!$D$9*Assumptions!$G$9*J12 -> 0 | ... BJ19: =Assumptions!$D$9*Assumptions!$G$9*BJ12 -> 1.73565
A20: Pain management practices | C20: =Assumptions!$D$10*Assumptions!$G$10*C13 -> 0 | D20: =Assumptions!$D$10*Assumptions!$G$10*D13 -> 0 | E20: =Assumptions!$D$10*Assumptions!$G$10*E13 -> 0 | F20: =Assumptions!$D$10*Assumptions!$G$10*F13 -> 0 | G20: =Assumptions!$D$10*Assumptions!$G$10*G13 -> 0 | H20: =Assumptions!$D$10*Assumptions!$G$10*H13 -> 0 | I20: =Assumptions!$D$10*Assumptions!$G$10*I13 -> 0 | J20: =Assumptions!$D$10*Assumptions!$G$10*J13 -> 0 | ... BJ20: =Assumptions!$D$10*Assumptions!$G$10*BJ13 -> 1.225
A22: Active customers (end of month)
A23: Chiropractic clinics | C23: =C16 -> 1.9267792 | D23: =C23*(1-Assumptions!$D$26)+D16 -> 5.732168 | E23: =D23*(1-Assumptions!$D$26)+E16 -> 11.369201 | F23: =E23*(1-Assumptions!$D$26)+F16 -> 18.792088 | G23: =F23*(1-Assumptions!$D$26)+G16 -> 27.956182 | H23: =G23*(1-Assumptions!$D$26)+H16 -> 38.817952 | I23: =H23*(1-Assumptions!$D$26)+I16 -> 51.334957 | J23: =I23*(1-Assumptions!$D$26)+J16 -> 65.465817 | K23: =J23*(1-Assumptions!$D$26)+K16 -> 81.170184 | ... BJ23: =BI23*(1-Assumptions!$D$26)+BJ16 -> 691.249
A24: Physical therapy clinics | C24: =C17 -> 0 | D24: =C24*(1-Assumptions!$D$26)+D17 -> 0 | E24: =D24*(1-Assumptions!$D$26)+E17 -> 0 | F24: =E24*(1-Assumptions!$D$26)+F17 -> 0 | G24: =F24*(1-Assumptions!$D$26)+G17 -> 0 | H24: =G24*(1-Assumptions!$D$26)+H17 -> 0 | I24: =H24*(1-Assumptions!$D$26)+I17 -> 0.455 | J24: =I24*(1-Assumptions!$D$26)+J17 -> 1.353625 | K24: =J24*(1-Assumptions!$D$26)+K17 -> 2.6847844 | ... BJ24: =BI24*(1-Assumptions!$D$26)+BJ17 -> 154.18538
A25: Medical injury clinics (MD/DO, urgent care treating PI) | C25: =C18 -> 0 | D25: =C25*(1-Assumptions!$D$26)+D18 -> 0 | E25: =D25*(1-Assumptions!$D$26)+E18 -> 0 | F25: =E25*(1-Assumptions!$D$26)+F18 -> 0 | G25: =F25*(1-Assumptions!$D$26)+G18 -> 0 | H25: =G25*(1-Assumptions!$D$26)+H18 -> 0 | I25: =H25*(1-Assumptions!$D$26)+I18 -> 0.2 | J25: =I25*(1-Assumptions!$D$26)+J18 -> 0.595 | K25: =J25*(1-Assumptions!$D$26)+K18 -> 1.180125 | ... BJ25: =BI25*(1-Assumptions!$D$26)+BJ18 -> 67.773795
A26: Orthopedic practices | C26: =C19 -> 0 | D26: =C26*(1-Assumptions!$D$26)+D19 -> 0 | E26: =D26*(1-Assumptions!$D$26)+E19 -> 0 | F26: =E26*(1-Assumptions!$D$26)+F19 -> 0 | G26: =F26*(1-Assumptions!$D$26)+G19 -> 0 | H26: =G26*(1-Assumptions!$D$26)+H19 -> 0 | I26: =H26*(1-Assumptions!$D$26)+I19 -> 0 | J26: =I26*(1-Assumptions!$D$26)+J19 -> 0 | K26: =J26*(1-Assumptions!$D$26)+K19 -> 0 | ... BJ26: =BI26*(1-Assumptions!$D$26)+BJ19 -> 41.766265
A27: Pain management practices | C27: =C20 -> 0 | D27: =C27*(1-Assumptions!$D$26)+D20 -> 0 | E27: =D27*(1-Assumptions!$D$26)+E20 -> 0 | F27: =E27*(1-Assumptions!$D$26)+F20 -> 0 | G27: =F27*(1-Assumptions!$D$26)+G20 -> 0 | H27: =G27*(1-Assumptions!$D$26)+H20 -> 0 | I27: =H27*(1-Assumptions!$D$26)+I20 -> 0 | J27: =I27*(1-Assumptions!$D$26)+J20 -> 0 | K27: =J27*(1-Assumptions!$D$26)+K20 -> 0 | ... BJ27: =BI27*(1-Assumptions!$D$26)+BJ20 -> 29.478106
A29: Total new customers | C29: =SUM(C16:C20) -> 1.9267792 | D29: =SUM(D16:D20) -> 3.8535583 | E29: =SUM(E16:E20) -> 5.7803375 | F29: =SUM(F16:F20) -> 7.7071167 | G29: =SUM(G16:G20) -> 9.6338958 | H29: =SUM(H16:H20) -> 11.560675 | I29: =SUM(I16:I20) -> 14.142454 | J29: =SUM(J16:J20) -> 16.724233 | ... BJ29: =SUM(BJ16:BJ20) -> 33.942
A30: Customers lost (churn) | C30: 0 | D30: =C31*Assumptions!$D$26 -> 0.048169479 | E30: =D31*Assumptions!$D$26 -> 0.1433042 | F30: =E31*Assumptions!$D$26 -> 0.28423003 | G30: =F31*Assumptions!$D$26 -> 0.4698022 | H30: =G31*Assumptions!$D$26 -> 0.69890454 | I30: =H31*Assumptions!$D$26 -> 0.9704488 | J30: =I31*Assumptions!$D$26 -> 1.2997489 | K30: =J31*Assumptions!$D$26 -> 1.685361 | ... BJ30: =BI31*Assumptions!$D$26 -> 24.372066
A31: Total active customers | C31: =SUM(C23:C27) -> 1.9267792 | D31: =SUM(D23:D27) -> 5.732168 | E31: =SUM(E23:E27) -> 11.369201 | F31: =SUM(F23:F27) -> 18.792088 | G31: =SUM(G23:G27) -> 27.956182 | H31: =SUM(H23:H27) -> 38.817952 | I31: =SUM(I23:I27) -> 51.989957 | J31: =SUM(J23:J27) -> 67.414442 | ... BJ31: =SUM(BJ23:BJ27) -> 984.45255
A33: MRR ($) | C33: =SUMPRODUCT(C23:C27,Assumptions!$I$6:$I$10)*Assumptions!$B$22/Assumptions!$B$21*C6 -> 98.843771 | D33: =SUMPRODUCT(D23:D27,Assumptions!$I$6:$I$10)*Assumptions!$B$22/Assumptions!$B$21*D6 -> 294.06022 | E33: =SUMPRODUCT(E23:E27,Assumptions!$I$6:$I$10)*Assumptions!$B$22/Assumptions!$B$21*E6 -> 583.24003 | F33: =SUMPRODUCT(F23:F27,Assumptions!$I$6:$I$10)*Assumptions!$B$22/Assumptions!$B$21*F6 -> 964.03411 | G33: =SUMPRODUCT(G23:G27,Assumptions!$I$6:$I$10)*Assumptions!$B$22/Assumptions!$B$21*G6 -> 1434.1521 | H33: =SUMPRODUCT(H23:H27,Assumptions!$I$6:$I$10)*Assumptions!$B$22/Assumptions!$B$21*H6 -> 1991.3609 | I33: =SUMPRODUCT(I23:I27,Assumptions!$I$6:$I$10)*Assumptions!$B$22/Assumptions!$B$21*I6 -> 2670.958 | J33: =SUMPRODUCT(J23:J27,Assumptions!$I$6:$I$10)*Assumptions!$B$22/Assumptions!$B$21*J6 -> 3469.8835 | ... BJ33: =SUMPRODUCT(BJ23:BJ27,Assumptions!$I$6:$I$10)*Assumptions!$B$22/Assumptions!$B$21*BJ6 -> 59963.554
A34: ARR ($) | C34: =C33*12 -> 1186.1253 | D34: =D33*12 -> 3528.7226 | E34: =E33*12 -> 6998.8803 | F34: =F33*12 -> 11568.409 | G34: =G33*12 -> 17209.825 | H34: =H33*12 -> 23896.331 | I34: =I33*12 -> 32051.496 | J34: =J33*12 -> 41638.602 | ... BJ34: =BJ33*12 -> 719562.65
A35: Revenue ($) | C35: =C33 -> 98.843771 | D35: =D33 -> 294.06022 | E35: =E33 -> 583.24003 | F35: =F33 -> 964.03411 | G35: =G33 -> 1434.1521 | H35: =H33 -> 1991.3609 | I35: =I33 -> 2670.958 | J35: =J33 -> 3469.8835 | ... BJ35: =BJ33 -> 59963.554
A37: Cost of revenue
A38: Card processing | C38: =C35*Assumptions!$B$33+C31*((1-Assumptions!$B$19)+Assumptions!$B$19/12)*Assumptions!$B$34 -> 3.2855438 | D38: =D35*Assumptions!$B$33+D31*((1-Assumptions!$B$19)+Assumptions!$B$19/12)*Assumptions!$B$34 -> 9.7744929 | E38: =E35*Assumptions!$B$33+E31*((1-Assumptions!$B$19)+Assumptions!$B$19/12)*Assumptions!$B$34 -> 19.386762 | F38: =F35*Assumptions!$B$33+F31*((1-Assumptions!$B$19)+Assumptions!$B$19/12)*Assumptions!$B$34 -> 32.044268 | G38: =G35*Assumptions!$B$33+G31*((1-Assumptions!$B$19)+Assumptions!$B$19/12)*Assumptions!$B$34 -> 47.670881 | H38: =H35*Assumptions!$B$33+H31*((1-Assumptions!$B$19)+Assumptions!$B$19/12)*Assumptions!$B$34 -> 66.192372 | I38: =I35*Assumptions!$B$33+I31*((1-Assumptions!$B$19)+Assumptions!$B$19/12)*Assumptions!$B$34 -> 88.765597 | J38: =J35*Assumptions!$B$33+J31*((1-Assumptions!$B$19)+Assumptions!$B$19/12)*Assumptions!$B$34 -> 115.28926 | ... BJ38: =BJ35*Assumptions!$B$33+BJ31*((1-Assumptions!$B$19)+Assumptions!$B$19/12)*Assumptions!$B$34 -> 1953.0615
A39: Hosting | C39: =Assumptions!$B$35+Assumptions!$B$36*C31 -> 251.44508 | D39: =Assumptions!$B$35+Assumptions!$B$36*D31 -> 254.29913 | E39: =Assumptions!$B$35+Assumptions!$B$36*E31 -> 258.5269 | F39: =Assumptions!$B$35+Assumptions!$B$36*F31 -> 264.09407 | G39: =Assumptions!$B$35+Assumptions!$B$36*G31 -> 270.96714 | H39: =Assumptions!$B$35+Assumptions!$B$36*H31 -> 279.11346 | I39: =Assumptions!$B$35+Assumptions!$B$36*I31 -> 288.99247 | J39: =Assumptions!$B$35+Assumptions!$B$36*J31 -> 300.56083 | ... BJ39: =Assumptions!$B$35+Assumptions!$B$36*BJ31 -> 988.33942
A40: Customer support | C40: =C31/Assumptions!$B$37*Assumptions!$B$38/12 -> 22.077678 | D40: =D31/Assumptions!$B$37*Assumptions!$B$38/12 -> 65.681092 | E40: =E31/Assumptions!$B$37*Assumptions!$B$38/12 -> 130.2721 | F40: =F31/Assumptions!$B$37*Assumptions!$B$38/12 -> 215.32601 | G40: =G31/Assumptions!$B$37*Assumptions!$B$38/12 -> 320.33125 | H40: =H31/Assumptions!$B$37*Assumptions!$B$38/12 -> 444.78903 | I40: =I31/Assumptions!$B$37*Assumptions!$B$38/12 -> 595.71826 | J40: =J31/Assumptions!$B$37*Assumptions!$B$38/12 -> 772.45715 | ... BJ40: =BJ31/Assumptions!$B$37*Assumptions!$B$38/12 -> 11280.186
A41: Total cost of revenue | C41: =SUM(C38:C40) -> 276.80831 | D41: =SUM(D38:D40) -> 329.75471 | E41: =SUM(E38:E40) -> 408.18576 | F41: =SUM(F38:F40) -> 511.46434 | G41: =SUM(G38:G40) -> 638.96926 | H41: =SUM(H38:H40) -> 790.09487 | I41: =SUM(I38:I40) -> 973.47633 | J41: =SUM(J38:J40) -> 1188.3072 | ... BJ41: =SUM(BJ38:BJ40) -> 14221.586
A42: Gross profit | C42: =C35-C41 -> -177.96453 | D42: =D35-D41 -> -35.694491 | E42: =E35-E41 -> 175.05427 | F42: =F35-F41 -> 452.56977 | G42: =G35-G41 -> 795.18285 | H42: =H35-H41 -> 1201.2661 | I42: =I35-I41 -> 1697.4816 | J42: =J35-J41 -> 2281.5762 | ... BJ42: =BJ35-BJ41 -> 45741.967
A43: Gross margin % | C43: =IF(C35=0,0,C42/C35) -> -1.8004628 | D43: =IF(D35=0,0,D42/D35) -> -0.12138497 | E43: =IF(E35=0,0,E42/E35) -> 0.30014104 | F43: =IF(F35=0,0,F42/F35) -> 0.4694541 | G43: =IF(G35=0,0,G42/G35) -> 0.554462 | H43: =IF(H35=0,0,H42/H35) -> 0.60323874 | I43: =IF(I35=0,0,I42/I35) -> 0.63553289 | J43: =IF(J35=0,0,J42/J35) -> 0.65753685 | ... BJ43: =IF(BJ35=0,0,BJ42/BJ35) -> 0.76282949
A45: Operating expenses
A46: Engineering | C46: =INDEX(Assumptions!$B$50:$F$50,C5)*Assumptions!$B$39/12 -> 2916.6667 | D46: =INDEX(Assumptions!$B$50:$F$50,D5)*Assumptions!$B$39/12 -> 2916.6667 | E46: =INDEX(Assumptions!$B$50:$F$50,E5)*Assumptions!$B$39/12 -> 2916.6667 | F46: =INDEX(Assumptions!$B$50:$F$50,F5)*Assumptions!$B$39/12 -> 2916.6667 | G46: =INDEX(Assumptions!$B$50:$F$50,G5)*Assumptions!$B$39/12 -> 2916.6667 | H46: =INDEX(Assumptions!$B$50:$F$50,H5)*Assumptions!$B$39/12 -> 2916.6667 | I46: =INDEX(Assumptions!$B$50:$F$50,I5)*Assumptions!$B$39/12 -> 2916.6667 | J46: =INDEX(Assumptions!$B$50:$F$50,J5)*Assumptions!$B$39/12 -> 2916.6667 | ... BJ46: =INDEX(Assumptions!$B$50:$F$50,BJ5)*Assumptions!$B$39/12 -> 23333.333
A47: Founder salary | C47: =INDEX(Assumptions!$B$51:$F$51,C5)/12 -> 0 | D47: =INDEX(Assumptions!$B$51:$F$51,D5)/12 -> 0 | E47: =INDEX(Assumptions!$B$51:$F$51,E5)/12 -> 0 | F47: =INDEX(Assumptions!$B$51:$F$51,F5)/12 -> 0 | G47: =INDEX(Assumptions!$B$51:$F$51,G5)/12 -> 0 | H47: =INDEX(Assumptions!$B$51:$F$51,H5)/12 -> 0 | I47: =INDEX(Assumptions!$B$51:$F$51,I5)/12 -> 0 | J47: =INDEX(Assumptions!$B$51:$F$51,J5)/12 -> 0 | ... BJ47: =INDEX(Assumptions!$B$51:$F$51,BJ5)/12 -> 10000
A48: Sales & marketing | C48: =C29*Assumptions!$D$27+Assumptions!$B$40 -> 2367.0506 | D48: =D29*Assumptions!$D$27+Assumptions!$B$40 -> 3234.1013 | E48: =E29*Assumptions!$D$27+Assumptions!$B$40 -> 4101.1519 | F48: =F29*Assumptions!$D$27+Assumptions!$B$40 -> 4968.2025 | G48: =G29*Assumptions!$D$27+Assumptions!$B$40 -> 5835.2531 | H48: =H29*Assumptions!$D$27+Assumptions!$B$40 -> 6702.3038 | I48: =I29*Assumptions!$D$27+Assumptions!$B$40 -> 7864.1044 | J48: =J29*Assumptions!$D$27+Assumptions!$B$40 -> 9025.905 | ... BJ48: =BJ29*Assumptions!$D$27+Assumptions!$B$40 -> 16773.9
...

Sheet Monthly Aggressive
A1: Monthly projection — Aggressive scenario
A2: All values are formulas driven by the Assumptions sheet.
A4: Month | C4: 1 | D4: 2 | E4: 3 | F4: 4 | G4: 5 | H4: 6 | I4: 7 | J4: 8 | K4: 9 | L4: 10 | M4: 11 | N4: 12 | O4: 13 | P4: 14 | Q4: 15 | R4: 16 | S4: 17 | T4: 18 | U4: 19 | V4: 20 | W4: 21 | X4: 22 | Y4: 23 | Z4: 24 | AA4: 25 | AB4: 26 | AC4: 27 | AD4: 28 | AE4: 29 | AF4: 30 | AG4: 31 | AH4: 32 | AI4: 33 | AJ4: 34 | AK4: 35 | AL4: 36 | AM4: 37 | AN4: 38 | AO4: 39 | AP4: 40 | AQ4: 41 | AR4: 42 | AS4: 43 | AT4: 44 | AU4: 45 | AV4: 46 | AW4: 47 | AX4: 48 | AY4: 49 | AZ4: 50 | BA4: 51 | BB4: 52 | BC4: 53 | BD4: 54 | BE4: 55 | BF4: 56 | BG4: 57 | BH4: 58 | BI4: 59 | BJ4: 60
A5: Year | C5: =INT((C4-1)/12)+1 -> 1 | D5: =INT((D4-1)/12)+1 -> 1 | E5: =INT((E4-1)/12)+1 -> 1 | F5: =INT((F4-1)/12)+1 -> 1 | G5: =INT((G4-1)/12)+1 -> 1 | H5: =INT((H4-1)/12)+1 -> 1 | I5: =INT((I4-1)/12)+1 -> 1 | J5: =INT((J4-1)/12)+1 -> 1 | ... BJ5: =INT((BJ4-1)/12)+1 -> 5
A6: Price factor (increases × list multiplier) | C6: =(1+Assumptions!$E$28)^(C5-1)*Assumptions!$B$21 -> 1 | D6: =(1+Assumptions!$E$28)^(D5-1)*Assumptions!$B$21 -> 1 | E6: =(1+Assumptions!$E$28)^(E5-1)*Assumptions!$B$21 -> 1 | F6: =(1+Assumptions!$E$28)^(F5-1)*Assumptions!$B$21 -> 1 | G6: =(1+Assumptions!$E$28)^(G5-1)*Assumptions!$B$21 -> 1 | H6: =(1+Assumptions!$E$28)^(H5-1)*Assumptions!$B$21 -> 1 | I6: =(1+Assumptions!$E$28)^(I5-1)*Assumptions!$B$21 -> 1 | J6: =(1+Assumptions!$E$28)^(J5-1)*Assumptions!$B$21 -> 1 | ... BJ6: =(1+Assumptions!$E$28)^(BJ5-1)*Assumptions!$B$21 -> 1.2155063
A8: Marketing ramp by segment
A9: Chiropractic clinics | C9: =IF(C4<Assumptions!$E$6,0,MIN(1,(C4-Assumptions!$E$6+1)/Assumptions!$E$29)) -> 0.11111111 | D9: =IF(D4<Assumptions!$E$6,0,MIN(1,(D4-Assumptions!$E$6+1)/Assumptions!$E$29)) -> 0.22222222 | E9: =IF(E4<Assumptions!$E$6,0,MIN(1,(E4-Assumptions!$E$6+1)/Assumptions!$E$29)) -> 0.33333333 | F9: =IF(F4<Assumptions!$E$6,0,MIN(1,(F4-Assumptions!$E$6+1)/Assumptions!$E$29)) -> 0.44444444 | G9: =IF(G4<Assumptions!$E$6,0,MIN(1,(G4-Assumptions!$E$6+1)/Assumptions!$E$29)) -> 0.55555556 | H9: =IF(H4<Assumptions!$E$6,0,MIN(1,(H4-Assumptions!$E$6+1)/Assumptions!$E$29)) -> 0.66666667 | I9: =IF(I4<Assumptions!$E$6,0,MIN(1,(I4-Assumptions!$E$6+1)/Assumptions!$E$29)) -> 0.77777778 | J9: =IF(J4<Assumptions!$E$6,0,MIN(1,(J4-Assumptions!$E$6+1)/Assumptions!$E$29)) -> 0.88888889 | ... BJ9: =IF(BJ4<Assumptions!$E$6,0,MIN(1,(BJ4-Assumptions!$E$6+1)/Assumptions!$E$29)) -> 1
A10: Physical therapy clinics | C10: =IF(C4<Assumptions!$E$7,0,MIN(1,(C4-Assumptions!$E$7+1)/Assumptions!$E$29)) -> 0 | D10: =IF(D4<Assumptions!$E$7,0,MIN(1,(D4-Assumptions!$E$7+1)/Assumptions!$E$29)) -> 0 | E10: =IF(E4<Assumptions!$E$7,0,MIN(1,(E4-Assumptions!$E$7+1)/Assumptions!$E$29)) -> 0 | F10: =IF(F4<Assumptions!$E$7,0,MIN(1,(F4-Assumptions!$E$7+1)/Assumptions!$E$29)) -> 0 | G10: =IF(G4<Assumptions!$E$7,0,MIN(1,(G4-Assumptions!$E$7+1)/Assumptions!$E$29)) -> 0 | H10: =IF(H4<Assumptions!$E$7,0,MIN(1,(H4-Assumptions!$E$7+1)/Assumptions!$E$29)) -> 0 | I10: =IF(I4<Assumptions!$E$7,0,MIN(1,(I4-Assumptions!$E$7+1)/Assumptions!$E$29)) -> 0.11111111 | J10: =IF(J4<Assumptions!$E$7,0,MIN(1,(J4-Assumptions!$E$7+1)/Assumptions!$E$29)) -> 0.22222222 | ... BJ10: =IF(BJ4<Assumptions!$E$7,0,MIN(1,(BJ4-Assumptions!$E$7+1)/Assumptions!$E$29)) -> 1
A11: Medical injury clinics (MD/DO, urgent care treating PI) | C11: =IF(C4<Assumptions!$E$8,0,MIN(1,(C4-Assumptions!$E$8+1)/Assumptions!$E$29)) -> 0 | D11: =IF(D4<Assumptions!$E$8,0,MIN(1,(D4-Assumptions!$E$8+1)/Assumptions!$E$29)) -> 0 | E11: =IF(E4<Assumptions!$E$8,0,MIN(1,(E4-Assumptions!$E$8+1)/Assumptions!$E$29)) -> 0 | F11: =IF(F4<Assumptions!$E$8,0,MIN(1,(F4-Assumptions!$E$8+1)/Assumptions!$E$29)) -> 0 | G11: =IF(G4<Assumptions!$E$8,0,MIN(1,(G4-Assumptions!$E$8+1)/Assumptions!$E$29)) -> 0 | H11: =IF(H4<Assumptions!$E$8,0,MIN(1,(H4-Assumptions!$E$8+1)/Assumptions!$E$29)) -> 0 | I11: =IF(I4<Assumptions!$E$8,0,MIN(1,(I4-Assumptions!$E$8+1)/Assumptions!$E$29)) -> 0.11111111 | J11: =IF(J4<Assumptions!$E$8,0,MIN(1,(J4-Assumptions!$E$8+1)/Assumptions!$E$29)) -> 0.22222222 | ... BJ11: =IF(BJ4<Assumptions!$E$8,0,MIN(1,(BJ4-Assumptions!$E$8+1)/Assumptions!$E$29)) -> 1
A12: Orthopedic practices | C12: =IF(C4<Assumptions!$E$9,0,MIN(1,(C4-Assumptions!$E$9+1)/Assumptions!$E$29)) -> 0 | D12: =IF(D4<Assumptions!$E$9,0,MIN(1,(D4-Assumptions!$E$9+1)/Assumptions!$E$29)) -> 0 | E12: =IF(E4<Assumptions!$E$9,0,MIN(1,(E4-Assumptions!$E$9+1)/Assumptions!$E$29)) -> 0 | F12: =IF(F4<Assumptions!$E$9,0,MIN(1,(F4-Assumptions!$E$9+1)/Assumptions!$E$29)) -> 0 | G12: =IF(G4<Assumptions!$E$9,0,MIN(1,(G4-Assumptions!$E$9+1)/Assumptions!$E$29)) -> 0 | H12: =IF(H4<Assumptions!$E$9,0,MIN(1,(H4-Assumptions!$E$9+1)/Assumptions!$E$29)) -> 0 | I12: =IF(I4<Assumptions!$E$9,0,MIN(1,(I4-Assumptions!$E$9+1)/Assumptions!$E$29)) -> 0 | J12: =IF(J4<Assumptions!$E$9,0,MIN(1,(J4-Assumptions!$E$9+1)/Assumptions!$E$29)) -> 0 | ... BJ12: =IF(BJ4<Assumptions!$E$9,0,MIN(1,(BJ4-Assumptions!$E$9+1)/Assumptions!$E$29)) -> 1
A13: Pain management practices | C13: =IF(C4<Assumptions!$E$10,0,MIN(1,(C4-Assumptions!$E$10+1)/Assumptions!$E$29)) -> 0 | D13: =IF(D4<Assumptions!$E$10,0,MIN(1,(D4-Assumptions!$E$10+1)/Assumptions!$E$29)) -> 0 | E13: =IF(E4<Assumptions!$E$10,0,MIN(1,(E4-Assumptions!$E$10+1)/Assumptions!$E$29)) -> 0 | F13: =IF(F4<Assumptions!$E$10,0,MIN(1,(F4-Assumptions!$E$10+1)/Assumptions!$E$29)) -> 0 | G13: =IF(G4<Assumptions!$E$10,0,MIN(1,(G4-Assumptions!$E$10+1)/Assumptions!$E$29)) -> 0 | H13: =IF(H4<Assumptions!$E$10,0,MIN(1,(H4-Assumptions!$E$10+1)/Assumptions!$E$29)) -> 0 | I13: =IF(I4<Assumptions!$E$10,0,MIN(1,(I4-Assumptions!$E$10+1)/Assumptions!$E$29)) -> 0 | J13: =IF(J4<Assumptions!$E$10,0,MIN(1,(J4-Assumptions!$E$10+1)/Assumptions!$E$29)) -> 0 | ... BJ13: =IF(BJ4<Assumptions!$E$10,0,MIN(1,(BJ4-Assumptions!$E$10+1)/Assumptions!$E$29)) -> 1
A15: New paying customers
A16: Chiropractic clinics | C16: =Assumptions!$D$6*Assumptions!$H$6*C9 -> 4.1104622 | D16: =Assumptions!$D$6*Assumptions!$H$6*D9 -> 8.2209244 | E16: =Assumptions!$D$6*Assumptions!$H$6*E9 -> 12.331387 | F16: =Assumptions!$D$6*Assumptions!$H$6*F9 -> 16.441849 | G16: =Assumptions!$D$6*Assumptions!$H$6*G9 -> 20.552311 | H16: =Assumptions!$D$6*Assumptions!$H$6*H9 -> 24.662773 | I16: =Assumptions!$D$6*Assumptions!$H$6*I9 -> 28.773236 | J16: =Assumptions!$D$6*Assumptions!$H$6*J9 -> 32.883698 | ... BJ16: =Assumptions!$D$6*Assumptions!$H$6*BJ9 -> 36.99416
A17: Physical therapy clinics | C17: =Assumptions!$D$7*Assumptions!$H$7*C10 -> 0 | D17: =Assumptions!$D$7*Assumptions!$H$7*D10 -> 0 | E17: =Assumptions!$D$7*Assumptions!$H$7*E10 -> 0 | F17: =Assumptions!$D$7*Assumptions!$H$7*F10 -> 0 | G17: =Assumptions!$D$7*Assumptions!$H$7*G10 -> 0 | H17: =Assumptions!$D$7*Assumptions!$H$7*H10 -> 0 | I17: =Assumptions!$D$7*Assumptions!$H$7*I10 -> 1.04 | J17: =Assumptions!$D$7*Assumptions!$H$7*J10 -> 2.08 | ... BJ17: =Assumptions!$D$7*Assumptions!$H$7*BJ10 -> 9.36
A18: Medical injury clinics (MD/DO, urgent care treating PI) | C18: =Assumptions!$D$8*Assumptions!$H$8*C11 -> 0 | D18: =Assumptions!$D$8*Assumptions!$H$8*D11 -> 0 | E18: =Assumptions!$D$8*Assumptions!$H$8*E11 -> 0 | F18: =Assumptions!$D$8*Assumptions!$H$8*F11 -> 0 | G18: =Assumptions!$D$8*Assumptions!$H$8*G11 -> 0 | H18: =Assumptions!$D$8*Assumptions!$H$8*H11 -> 0 | I18: =Assumptions!$D$8*Assumptions!$H$8*I11 -> 0.46666667 | J18: =Assumptions!$D$8*Assumptions!$H$8*J11 -> 0.93333333 | ... BJ18: =Assumptions!$D$8*Assumptions!$H$8*BJ11 -> 4.2
